Workbook

Sheet README
A1: Plantilla SGSI – Controles ISO/IEC 27001:2022 (93 controles)
A3: Uso:
A4: 1) Complete en 'Controles' el estado, SoA, evidencias, responsable y riesgos.
A5: 2) Registre riesgos en 'Riesgos' y vincule el ID al control (Riesgo principal).
A6: 3) Revise 'Dashboard' para ver porcentajes por dominio y alertas.
A8: Listas desplegables:
A9: - Estado: Implementado / En proceso / No implementado / No aplicable
A11: Referencias (URLs):
A12: ISO/IEC 27001:2022: https://www.iso.org/standard/27001
A13: ISO/IEC 27002:2022: https://www.iso.org/standard/75652.html

Sheet Controles
A1: Dominio | B1: Dominio (calc) | C1: Categoría | D1: Código | E1: Control (paráfrasis) | F1: Descripción (detalle) | G1: Actividad para cumplir | H1: Aplicable (Sí/No) | I1: Estado | J1: Justificación (SoA) | K1: Evidencias (enlaces/rutas) | L1: Responsable | M1: Riesgo principal (ID) | N1: Nivel de riesgo (lookup) | O1: Fecha objetivo | P1: Última revisión | Q1: Progreso % | R1: Alerta | S1: Notas
A2: A.5 | B2: DOM_A5 | C2: Organizacionales | D2: A.5.1 | E2: Política global y políticas temáticas de SI | F2: Define y mantiene la política de seguridad de la información y políticas temáticas; deben ser aprobadas, comunicadas, reconocidas y revisadas periódicamente. | G2: • Redactar política SGSI y políticas por tema • aprobar en alta dirección • publicar en repositorio oficial • comunicar y obtener acuse del personal • revisar al menos anual y ante cambios • gestionar excepciones. | H2: =IF($I2="No aplicable","No","Sí") | I2: Implementado | J2: Política aprobada por alta dirección; revisiones anuales y ante cambios. | K2: Doc: Política_SI_v1.2.pdf; Registro de comunicación; control de versiones. | L2: CISO | M2: R-002 | N2: =IFERROR(VLOOKUP($M2,Riesgos!$A$2:$E$200,5,FALSE),"") | O2: 46053 | P2: 46006 | Q2: 1 | R2: =IF($H2<>"Sí","",IF($I2="No implementado",IF(OR($N2="Muy alto",$N2="Alto"),"ALERTA ALTA","ALERTA"),IF(AND($I2="En proceso",OR($N2="Muy alto",$N2="Alto")),"EN PROCESO (riesgo alto)","")))
A3: A.5 | B3: DOM_A5 | C3: Organizacionales | D3: A.5.2 | E3: Roles y responsabilidades de SI | F3: Define y asigna roles, responsabilidades y autoridades de seguridad de la información de forma clara y entendible dentro de la organización. | G3: • Mapear funciones (RACI) • nombrar responsables por procesos/activos/riesgos • documentar responsabilidades y niveles de autorización • comunicar a cada rol • asegurar competencia/formación • revisar tras cambios organizacionales. | H3: =IF($I3="No aplicable","No","Sí") | N3: =IFERROR(VLOOKUP($M3,Riesgos!$A$2:$E$200,5,FALSE),"") | R3: =IF($H3<>"Sí","",IF($I3="No implementado",IF(OR($N3="Muy alto",$N3="Alto"),"ALERTA ALTA","ALERTA"),IF(AND($I3="En proceso",OR($N3="Muy alto",$N3="Alto")),"EN PROCESO (riesgo alto)","")))
A4: A.5 | B4: DOM_A5 | C4: Organizacionales | D4: A.5.3 | E4: Separación de funciones (segregación) | F4: Separa funciones y áreas de responsabilidad en conflicto para reducir fraude, error o elusión de controles. | G4: • Identificar actividades incompatibles (aprobar/ejecutar, solicitar/otorgar accesos, desarrollar/poner en prod) • diseñar segregación • configurar RBAC/PAM • aplicar revisiones independientes • definir controles compensatorios (logs/monitoreo) donde no sea posible segregar. | H4: =IF($I4="No aplicable","No","Sí") | N4: =IFERROR(VLOOKUP($M4,Riesgos!$A$2:$E$200,5,FALSE),"") | R4: =IF($H4<>"Sí","",IF($I4="No implementado",IF(OR($N4="Muy alto",$N4="Alto"),"ALERTA ALTA","ALERTA"),IF(AND($I4="En proceso",OR($N4="Muy alto",$N4="Alto")),"EN PROCESO (riesgo alto)","")))
A5: A.5 | B5: DOM_A5 | C5: Organizacionales | D5: A.5.4 | E5: Responsabilidades de la gestión en SI | F5: La dirección impulsa el cumplimiento de políticas y procedimientos de seguridad; asegura que el personal conoce y aplica sus responsabilidades. | G5: • Incluir seguridad en objetivos de gestión • exigir cumplimiento (onboarding antes de acceso) • proveer recursos y tiempo • asegurar capacitación continua • establecer canal confidencial de reportes • revisar cumplimiento y aplicar acciones correctivas. | H5: =IF($I5="No aplicable","No","Sí") | N5: =IFERROR(VLOOKUP($M5,Riesgos!$A$2:$E$200,5,FALSE),"") | R5: =IF($H5<>"Sí","",IF($I5="No implementado",IF(OR($N5="Muy alto",$N5="Alto"),"ALERTA ALTA","ALERTA"),IF(AND($I5="En proceso",OR($N5="Muy alto",$N5="Alto")),"EN PROCESO (riesgo alto)","")))
A6: A.5 | B6: DOM_A5 | C6: Organizacionales | D6: A.5.5 | E6: Contacto y coordinación con autoridades | F6: Establece y mantiene contactos con autoridades relevantes (regulatorias, supervisión, fuerzas de orden, servicios críticos) para incidentes y continuidad. | G6: • Identificar autoridades aplicables • mantener lista de contactos y criterios de activación • definir responsables de contacto • establecer procedimientos de notificación • probar el mecanismo (simulacros) • revisar contactos periódicamente. | H6: =IF($I6="No aplicable","No","Sí") | N6: =IFERROR(VLOOKUP($M6,Riesgos!$A$2:$E$200,5,FALSE),"") | R6: =IF($H6<>"Sí","",IF($I6="No implementado",IF(OR($N6="Muy alto",$N6="Alto"),"ALERTA ALTA","ALERTA"),IF(AND($I6="En proceso",OR($N6="Muy alto",$N6="Alto")),"EN PROCESO (riesgo alto)","")))
A7: A.5 | B7: DOM_A5 | C7: Organizacionales | D7: A.5.6 | E7: Vínculo con grupos/foros especializados | F7: Mantiene contacto con foros y grupos especializados para compartir buenas prácticas y recibir alertas tempranas de amenazas/vulnerabilidades. | G7: • Seleccionar foros sectoriales/CERT/ISAC • suscribir alertas • definir proceso de distribución interna • participar en sesiones • registrar aprendizajes • revisar utilidad y cobertura periódicamente. | H7: =IF($I7="No aplicable","No","Sí") | N7: =IFERROR(VLOOKUP($M7,Riesgos!$A$2:$E$200,5,FALSE),"") | R7: =IF($H7<>"Sí","",IF($I7="No implementado",IF(OR($N7="Muy alto",$N7="Alto"),"ALERTA ALTA","ALERTA"),IF(AND($I7="En proceso",OR($N7="Muy alto",$N7="Alto")),"EN PROCESO (riesgo alto)","")))
A8: A.5 | B8: DOM_A5 | C8: Organizacionales | D8: A.5.7 | E8: Inteligencia de amenazas (recopilar/analizar) | F8: Recopila y analiza información de amenazas para producir inteligencia accionable y apoyar decisiones de riesgo y controles. | G8: • Definir objetivos de threat intel • seleccionar fuentes (internas/externas) • recolectar y procesar datos • analizar (estratégico/táctico/operativo) • integrar resultados en gestión de riesgos y controles • comunicar a responsables y registrar acciones. | H8: =IF($I8="No aplicable","No","Sí") | N8: =IFERROR(VLOOKUP($M8,Riesgos!$A$2:$E$200,5,FALSE),"") | R8: =IF($H8<>"Sí","",IF($I8="No implementado",IF(OR($N8="Muy alto",$N8="Alto"),"ALERTA ALTA","ALERTA"),IF(AND($I8="En proceso",OR($N8="Muy alto",$N8="Alto")),"EN PROCESO (riesgo alto)","")))
A9: A.5 | B9: DOM_A5 | C9: Organizacionales | D9: A.5.8 | E9: SI integrada en la gestión de proyectos | F9: Integra seguridad de la información en la gestión de proyectos y en los entregables durante todo el ciclo de vida. | G9: • Incluir checklist de seguridad en metodología • ejecutar evaluación de riesgos del proyecto y del producto • definir requisitos de seguridad • incorporar gates/revisiones • asignar roles de seguridad del proyecto • validar controles en pruebas y aceptación. | H9: =IF($I9="No aplicable","No","Sí") | N9: =IFERROR(VLOOKUP($M9,Riesgos!$A$2:$E$200,5,FALSE),"") | R9: =IF($H9<>"Sí","",IF($I9="No implementado",IF(OR($N9="Muy alto",$N9="Alto"),"ALERTA ALTA","ALERTA"),IF(AND($I9="En proceso",OR($N9="Muy alto",$N9="Alto")),"EN PROCESO (riesgo alto)","")))
A10: A.5 | B10: DOM_A5 | C10: Organizacionales | D10: A.5.9 | E10: Inventario de información y activos asociados | F10: Mantiene un inventario de información y activos asociados, incluyendo propietarios, ubicación y clasificación, actualizado y coherente. | G10: • Inventariar activos (info, HW, SW, VM, servicios) • asignar propietarios • registrar ubicación y dependencia • clasificar según sensibilidad • definir proceso de alta/cambio/baja que actualice inventario • realizar revisiones periódicas. | H10: =IF($I10="No aplicable","No","Sí") | N10: =IFERROR(VLOOKUP($M10,Riesgos!$A$2:$E$200,5,FALSE),"") | R10: =IF($H10<>"Sí","",IF($I10="No implementado",IF(OR($N10="Muy alto",$N10="Alto"),"ALERTA ALTA","ALERTA"),IF(AND($I10="En proceso",OR($N10="Muy alto",$N10="Alto")),"EN PROCESO (riesgo alto)","")))
A11: A.5 | B11: DOM_A5 | C11: Organizacionales | D11: A.5.10 | E11: Reglas de uso aceptable de activos | F11: Define reglas de uso aceptable y procedimientos de manejo de información y activos para prevenir uso indebido o inseguro. | G11: • Publicar norma de uso aceptable (equipos, correo, internet, nube) • definir manejo por clasificación • comunicar y obtener aceptación • implementar controles técnicos (bloqueos, DLP básico) • revisar cumplimiento e incidentes. | H11: =IF($I11="No aplicable","No","Sí") | N11: =IFERROR(VLOOKUP($M11,Riesgos!$A$2:$E$200,5,FALSE),"") | R11: =IF($H11<>"Sí","",IF($I11="No implementado",IF(OR($N11="Muy alto",$N11="Alto"),"ALERTA ALTA","ALERTA"),IF(AND($I11="En proceso",OR($N11="Muy alto",$N11="Alto")),"EN PROCESO (riesgo alto)","")))
A12: A.5 | B12: DOM_A5 | C12: Organizacionales | D12: A.5.11 | E12: Devolución/retorno de activos | F12: Asegura el retorno de activos de la organización al término o cambio de relación laboral/contractual. | G12: • Definir lista de activos por rol • ejecutar checklist de devolución (HW, credenciales, documentos) • validar borrado/entrega de información • registrar evidencia • coordinar con RRHH y TI • auditar el proceso. | H12: =IF($I12="No aplicable","No","Sí") | N12: =IFERROR(VLOOKUP($M12,Riesgos!$A$2:$E$200,5,FALSE),"") | R12: =IF($H12<>"Sí","",IF($I12="No implementado",IF(OR($N12="Muy alto",$N12="Alto"),"ALERTA ALTA","ALERTA"),IF(AND($I12="En proceso",OR($N12="Muy alto",$N12="Alto")),"EN PROCESO (riesgo alto)","")))
A13: A.5 | B13: DOM_A5 | C13: Organizacionales | D13: A.5.12 | E13: Clasificación de la información | F13: Clasifica la información según criterios de confidencialidad, integridad y disponibilidad, y determina requisitos de protección. | G13: • Definir esquema de clasificación • capacitar a usuarios • clasificar información y activos • asociar controles por nivel (cifrado, acceso, retención) • revisar clasificación periódicamente • integrar en procesos y herramientas. | H13: =IF($I13="No aplicable","No","Sí") | N13: =IFERROR(VLOOKUP($M13,Riesgos!$A$2:$E$200,5,FALSE),"") | R13: =IF($H13<>"Sí","",IF($I13="No implementado",IF(OR($N13="Muy alto",$N13="Alto"),"ALERTA ALTA","ALERTA"),IF(AND($I13="En proceso",OR($N13="Muy alto",$N13="Alto")),"EN PROCESO (riesgo alto)","")))
A14: A.5 | B14: DOM_A5 | C14: Organizacionales | D14: A.5.13 | E14: Etiquetado/rotulado de la información | F14: Etiqueta información y activos asociados de acuerdo con su clasificación para facilitar el manejo correcto y consistente. | G14: • Definir estándar de etiquetado • aplicar etiquetas en documentos/sistemas/medios • configurar etiquetas en suites (M365/Google) • establecer reglas de tratamiento por etiqueta • controlar excepciones • auditar uso. | H14: =IF($I14="No aplicable","No","Sí") | N14: =IFERROR(VLOOKUP($M14,Riesgos!$A$2:$E$200,5,FALSE),"") | R14: =IF($H14<>"Sí","",IF($I14="No implementado",IF(OR($N14="Muy alto",$N14="Alto"),"ALERTA ALTA","ALERTA"),IF(AND($I14="En proceso",OR($N14="Muy alto",$N14="Alto")),"EN PROCESO (riesgo alto)","")))
... A23: A.5 | B23: DOM_A5 | C23: Organizacionales | D23: A.5.22 | E23: Supervisión, revisión y cambios de servicios del proveedor | F23: Monitorea, revisa y gestiona cambios en servicios de proveedores para asegurar que continúan cumpliendo requisitos de seguridad. | G23: • Definir revisiones periódicas • medir SLA/controles • gestionar cambios (avisos, evaluación de impacto) • revisar reportes de auditoría del proveedor • registrar no conformidades • ejecutar planes de mejora. | H23: =IF($I23="No aplicable","No","Sí") | N23: =IFERROR(VLOOKUP($M23,Riesgos!$A$2:$E$200,5,FALSE),"") | R23: =IF($H23<>"Sí","",IF($I23="No implementado",IF(OR($N23="Muy alto",$N23="Alto"),"ALERTA ALTA","ALERTA"),IF(AND($I23="En proceso",OR($N23="Muy alto",$N23="Alto")),"EN PROCESO (riesgo alto)","")))
A24: A.5 | B24: DOM_A5 | C24: Organizacionales | D24: A.5.23 | E24: Seguridad para uso de servicios en la nube | F24: Asegura el uso seguro de servicios en la nube, incluyendo gobierno, configuración segura y responsabilidades compartidas. | G24: • Definir política de uso de nube • evaluar proveedor y modelo de responsabilidad • configurar controles base (IAM, logging, cifrado) • revisar postura (CSPM si aplica) • definir plan de salida/portabilidad • gestionar accesos y datos. | H24: =IF($I24="No aplicable","No","Sí") | I24: En proceso | J24: Definir criterios de seguridad para proveedores cloud; evaluación de configuración y acuerdos. | K24: Checklist cloud; contrato con cláusulas SI; baseline CIS (si aplica). | L24: TI / Seguridad | M24: R-005 | N24: =IFERROR(VLOOKUP($M24,Riesgos!$A$2:$E$200,5,FALSE),"") | O24: 46112 | P24: 46001 | Q24: 0.4 | R24: =IF($H24<>"Sí","",IF($I24="No implementado",IF(OR($N24="Muy alto",$N24="Alto"),"ALERTA ALTA","ALERTA"),IF(AND($I24="En proceso",OR($N24="Muy alto",$N24="Alto")),"EN PROCESO (riesgo alto)","")))
A25: A.5 | B25: DOM_A5 | C25: Organizacionales | D25: A.5.24 | E25: Planificación y preparación para incidentes de SI | F25: Planifica y prepara la gestión de incidentes: procesos, roles, herramientas, comunicación y entrenamiento. | G25: • Definir plan IR y playbooks • asignar roles (IR lead, comunicaciones, legal) • preparar herramientas (ticketing, forense) • entrenar y hacer ejercicios • definir escalamiento • mantener lista de contactos y plantillas. | H25: =IF($I25="No aplicable","No","Sí") | N25: =IFERROR(VLOOKUP($M25,Riesgos!$A$2:$E$200,5,FALSE),"") | R25: =IF($H25<>"Sí","",IF($I25="No implementado",IF(OR($N25="Muy alto",$N25="Alto"),"ALERTA ALTA","ALERTA"),IF(AND($I25="En proceso",OR($N25="Muy alto",$N25="Alto")),"EN PROCESO (riesgo alto)","")))
A26: A.5 | B26: DOM_A5 | C26: Organizacionales | D26: A.5.25 | E26: Evaluación y decisión sobre eventos de SI | F26: Evalúa y decide sobre eventos de seguridad: clasificación, priorización y escalamiento oportuno. | G26: • Definir criterios de clasificación • establecer triage 24/7 o ventanas • registrar eventos • correlacionar y validar • decidir si es incidente • notificar a responsables • medir tiempos de respuesta. | H26: =IF($I26="No aplicable","No","Sí") | N26: =IFERROR(VLOOKUP($M26,Riesgos!$A$2:$E$200,5,FALSE),"") | R26: =IF($H26<>"Sí","",IF($I26="No implementado",IF(OR($N26="Muy alto",$N26="Alto"),"ALERTA ALTA","ALERTA"),IF(AND($I26="En proceso",OR($N26="Muy alto",$N26="Alto")),"EN PROCESO (riesgo alto)","")))
A27: A.5 | B27: DOM_A5 | C27: Organizacionales | D27: A.5.26 | E27: Respuesta a incidentes de SI | F27: Responde a incidentes de seguridad con acciones coordinadas de contención, erradicación, recuperación y comunicación. | G27: • Activar playbook • contener (aislar, bloquear) • preservar evidencias • erradicar causa raíz • recuperar servicios/datos • comunicar a stakeholders • documentar cronología y acciones • cerrar con reporte. | H27: =IF($I27="No aplicable","No","Sí") | N27: =IFERROR(VLOOKUP($M27,Riesgos!$A$2:$E$200,5,FALSE),"") | R27: =IF($H27<>"Sí","",IF($I27="No implementado",IF(OR($N27="Muy alto",$N27="Alto"),"ALERTA ALTA","ALERTA"),IF(AND($I27="En proceso",OR($N27="Muy alto",$N27="Alto")),"EN PROCESO (riesgo alto)","")))
A28: A.5 | B28: DOM_A5 | C28: Organizacionales | D28: A.5.27 | E28: Lecciones aprendidas de incidentes | F28: Aprende de los incidentes: análisis post-mortem, lecciones aprendidas y mejoras en controles y procesos. | G28: • Realizar post-incident review • identificar fallas y oportunidades • actualizar riesgos/controles/políticas • ejecutar acciones correctivas • compartir aprendizajes • medir recurrencia y eficacia. | H28: =IF($I28="No aplicable","No","Sí") | N28: =IFERROR(VLOOKUP($M28,Riesgos!$A$2:$E$200,5,FALSE),"") | R28: =IF($H28<>"Sí","",IF($I28="No implementado",IF(OR($N28="Muy alto",$N28="Alto"),"ALERTA ALTA","ALERTA"),IF(AND($I28="En proceso",OR($N28="Muy alto",$N28="Alto")),"EN PROCESO (riesgo alto)","")))
A29: A.5 | B29: DOM_A5 | C29: Organizacionales | D29: A.5.28 | E29: Recolección y preservación de evidencias | F29: Recolecta y preserva evidencias de manera forense para soportar investigaciones internas/legales manteniendo cadena de custodia. | G29: • Definir procedimiento forense • capacitar personal • usar herramientas aprobadas • mantener cadena de custodia • almacenar evidencias de forma segura • coordinar con legal • retener según requisitos. | H29: =IF($I29="No aplicable","No","Sí") | N29: =IFERROR(VLOOKUP($M29,Riesgos!$A$2:$E$200,5,FALSE),"") | R29: =IF($H29<>"Sí","",IF($I29="No implementado",IF(OR($N29="Muy alto",$N29="Alto"),"ALERTA ALTA","ALERTA"),IF(AND($I29="En proceso",OR($N29="Muy alto",$N29="Alto")),"EN PROCESO (riesgo alto)","")))
A30: A.5 | B30: DOM_A5 | C30: Organizacionales | D30: A.5.29 | E30: Seguridad de la información durante interrupciones | F30: Mantiene seguridad de la información durante interrupciones, asegurando que controles críticos siguen operando en modo degradado. | G30: • Definir controles mínimos en contingencia • establecer accesos de emergencia controlados • asegurar backups y comunicaciones • proteger información en sitios alternos • probar escenarios • registrar decisiones y excepciones. | H30: =IF($I30="No aplicable","No","Sí") | N30: =IFERROR(VLOOKUP($M30,Riesgos!$A$2:$E$200,5,FALSE),"") | R30: =IF($H30<>"Sí","",IF($I30="No implementado",IF(OR($N30="Muy alto",$N30="Alto"),"ALERTA ALTA","ALERTA"),IF(AND($I30="En proceso",OR($N30="Muy alto",$N30="Alto")),"EN PROCESO (riesgo alto)","")))
A31: A.5 | B31: DOM_A5 | C31: Organizacionales | D31: A.5.30 | E31: Preparación TIC para continuidad del negocio | F31: Asegura preparación TIC para continuidad del negocio: recuperación, respaldo, redundancia y pruebas de restauración/failover. | G31: • Definir RTO/RPO • diseñar DR/BCP de TI • implementar backups y replicación • probar restauración y conmutación • mantener runbooks • revisar cambios de infraestructura y actualizar planes. | H31: =IF($I31="No aplicable","No","Sí") | N31: =IFERROR(VLOOKUP($M31,Riesgos!$A$2:$E$200,5,FALSE),"") | R31: =IF($H31<>"Sí","",IF($I31="No implementado",IF(OR($N31="Muy alto",$N31="Alto"),"ALERTA ALTA","ALERTA"),IF(AND($I31="En proceso",OR($N31="Muy alto",$N31="Alto")),"EN PROCESO (riesgo alto)","")))
A32: A.5 | B32: DOM_A5 | C32: Organizacionales | D32: A.5.31 | E32: Requisitos legales/regulatorios/contractuales | F32: Identifica y cumple requisitos legales, regulatorios y contractuales aplicables a la seguridad de la información y privacidad. | G32: • Mantener matriz de cumplimiento • asignar responsables • implementar controles para requisitos • revisar cambios normativos • evidenciar cumplimiento • incorporar requisitos en contratos y políticas. | H32: =IF($I32="No aplicable","No","Sí") | N32: =IFERROR(VLOOKUP($M32,Riesgos!$A$2:$E$200,5,FALSE),"") | R32: =IF($H32<>"Sí","",IF($I32="No implementado",IF(OR($N32="Muy alto",$N32="Alto"),"ALERTA ALTA","ALERTA"),IF(AND($I32="En proceso",OR($N32="Muy alto",$N32="Alto")),"EN PROCESO (riesgo alto)","")))
A33: A.5 | B33: DOM_A5 | C33: Organizacionales | D33: A.5.32 | E33: Derechos de propiedad intelectual (DPI) | F33: Protege derechos de propiedad intelectual y asegura uso legal de software/datos/licencias. | G33: • Inventariar licencias y activos IP • definir reglas de uso y reproducción • controlar software no autorizado • revisar cumplimiento de licencias • gestionar contenido de terceros • registrar evidencias. | H33: =IF($I33="No aplicable","No","Sí") | N33: =IFERROR(VLOOKUP($M33,Riesgos!$A$2:$E$200,5,FALSE),"") | R33: =IF($H33<>"Sí","",IF($I33="No implementado",IF(OR($N33="Muy alto",$N33="Alto"),"ALERTA ALTA","ALERTA"),IF(AND($I33="En proceso",OR($N33="Muy alto",$N33="Alto")),"EN PROCESO (riesgo alto)","")))
A34: A.5 | B34: DOM_A5 | C34: Organizacionales | D34: A.5.33 | E34: Protección y retención de registros | F34: Protege registros (records) para asegurar su integridad, disponibilidad y trazabilidad durante su ciclo de vida y retención. | G34: • Definir política de gestión de registros • establecer retención y disposiciones • asegurar almacenamiento y backups • controlar accesos • proteger contra alteración • auditar registros críticos. | H34: =IF($I34="No aplicable","No","Sí") | N34: =IFERROR(VLOOKUP($M34,Riesgos!$A$2:$E$200,5,FALSE),"") | R34: =IF($H34<>"Sí","",IF($I34="No implementado",IF(OR($N34="Muy alto",$N34="Alto"),"ALERTA ALTA","ALERTA"),IF(AND($I34="En proceso",OR($N34="Muy alto",$N34="Alto")),"EN PROCESO (riesgo alto)","")))
A35: A.5 | B35: DOM_A5 | C35: Organizacionales | D35: A.5.34 | E35: Privacidad y protección de PII | F35: Gestiona privacidad y protección de información identificable (PII) conforme a requisitos aplicables, minimizando exposición y riesgo. | G35: • Inventariar PII y bases legales • aplicar minimización y controles de acceso • cifrar PII sensible • gestionar derechos de titulares • evaluar DPIA/PIA cuando aplique • monitorear incidentes y notificar según norma. | H35: =IF($I35="No aplicable","No","Sí") | N35: =IFERROR(VLOOKUP($M35,Riesgos!$A$2:$E$200,5,FALSE),"") | R35: =IF($H35<>"Sí","",IF($I35="No implementado",IF(OR($N35="Muy alto",$N35="Alto"),"ALERTA ALTA","ALERTA"),IF(AND($I35="En proceso",OR($N35="Muy alto",$N35="Alto")),"EN PROCESO (riesgo alto)","")))
A36: A.5 | B36: DOM_A5 | C36: Organizacionales | D36: A.5.35 | E36: Revisión independiente de SI | F36: Realiza revisiones independientes de seguridad para evaluar adecuación y eficacia de controles, políticas y procesos. | G36: • Planificar revisiones/auditorías internas • definir alcance y criterios • ejecutar pruebas y entrevistas • emitir hallazgos y recomendaciones • hacer seguimiento a acciones correctivas • reportar a dirección. | H36: =IF($I36="No aplicable","No","Sí") | N36: =IFERROR(VLOOKUP($M36,Riesgos!$A$2:$E$200,5,FALSE),"") | R36: =IF($H36<>"Sí","",IF($I36="No implementado",IF(OR($N36="Muy alto",$N36="Alto"),"ALERTA ALTA","ALERTA"),IF(AND($I36="En proceso",OR($N36="Muy alto",$N36="Alto")),"EN PROCESO (riesgo alto)","")))
... A40: A.6 | B40: DOM_A6 | C40: Personas | D40: A.6.2 | E40: Términos y condiciones de empleo | F40: Incluye obligaciones de seguridad en términos y condiciones de empleo/contrato, alineadas a políticas del SGSI. | G40: • Actualizar contratos y anexos • incluir confidencialidad, uso aceptable y sanciones • entregar políticas y obtener aceptación • asegurar onboarding • revisar en cambios de rol • mantener registros. | H40: =IF($I40="No aplicable","No","Sí") | N40: =IFERROR(VLOOKUP($M40,Riesgos!$A$2:$E$200,5,FALSE),"") | R40: =IF($H40<>"Sí","",IF($I40="No implementado",IF(OR($N40="Muy alto",$N40="Alto"),"ALERTA ALTA","ALERTA"),IF(AND($I40="En proceso",OR($N40="Muy alto",$N40="Alto")),"EN PROCESO (riesgo alto)","")))
A41: A.6 | B41: DOM_A6 | C41: Personas | D41: A.6.3 | E41: Concientización, educación y capacitación en SI | F41: Asegura concientización, educación y capacitación en seguridad acorde al rol y riesgos, de forma periódica. | G41: • Definir plan anual de formación • capacitar por rol (general y especializado) • realizar campañas (phishing, posters) • evaluar efectividad • registrar participación • actualizar contenidos según incidentes. | H41: =IF($I41="No aplicable","No","Sí") | I41: En proceso | J41: Plan anual de concientización, onboarding y formación por rol; métricas de asistencia. | K41: Plan de formación; registros de asistencia; resultados de phishing simulado. | L41: RR.HH. / CISO | M41: R-007 | N41: =IFERROR(VLOOKUP($M41,Riesgos!$A$2:$E$200,5,FALSE),"") | O41: 46081 | P41: 45992 | Q41: 0.25 | R41: =IF($H41<>"Sí","",IF($I41="No implementado",IF(OR($N41="Muy alto",$N41="Alto"),"ALERTA ALTA","ALERTA"),IF(AND($I41="En proceso",OR($N41="Muy alto",$N41="Alto")),"EN PROCESO (riesgo alto)","")))
A42: A.6 | B42: DOM_A6 | C42: Personas | D42: A.6.4 | E42: Proceso disciplinario relacionado con SI | F42: Establece un proceso disciplinario para tratar violaciones a políticas y controles de seguridad. | G42: • Definir política disciplinaria • clasificar severidad • coordinar con RRHH y legal • aplicar medidas consistentes • registrar casos • retroalimentar al SGSI para prevención. | H42: =IF($I42="No aplicable","No","Sí") | N42: =IFERROR(VLOOKUP($M42,Riesgos!$A$2:$E$200,5,FALSE),"") | R42: =IF($H42<>"Sí","",IF($I42="No implementado",IF(OR($N42="Muy alto",$N42="Alto"),"ALERTA ALTA","ALERTA"),IF(AND($I42="En proceso",OR($N42="Muy alto",$N42="Alto")),"EN PROCESO (riesgo alto)","")))
A43: A.6 | B43: DOM_A6 | C43: Personas | D43: A.6.5 | E43: Responsabilidades tras cese o cambio de empleo | F43: Gestiona responsabilidades tras cese o cambio de empleo, asegurando revocación de accesos y devolución de activos. | G43: • Activar proceso JML con RRHH • revocar accesos y credenciales • retirar privilegios • recuperar activos • asegurar continuidad de responsabilidades • registrar cierre y evidencias. | H43: =IF($I43="No aplicable","No","Sí") | N43: =IFERROR(VLOOKUP($M43,Riesgos!$A$2:$E$200,5,FALSE),"") | R43: =IF($H43<>"Sí","",IF($I43="No implementado",IF(OR($N43="Muy alto",$N43="Alto"),"ALERTA ALTA","ALERTA"),IF(AND($I43="En proceso",OR($N43="Muy alto",$N43="Alto")),"EN PROCESO (riesgo alto)","")))
A44: A.6 | B44: DOM_A6 | C44: Personas | D44: A.6.6 | E44: Acuerdos de confidencialidad / no divulgación | F44: Asegura acuerdos de confidencialidad/NDA con empleados, contratistas y terceros con acceso a información sensible. | G44: • Definir plantillas NDA • firmar antes de acceso • almacenar y controlar vigencia • incluir obligaciones post-empleo • revisar para terceros • auditar cobertura. | H44: =IF($I44="No aplicable","No","Sí") | I44: Implementado | J44: NDA firmado por empleados/contratistas antes de acceso; repositorio controlado. | K44: Plantilla NDA; evidencias firmadas; control de acceso al repositorio. | L44: RR.HH. | M44: R-002 | N44: =IFERROR(VLOOKUP($M44,Riesgos!$A$2:$E$200,5,FALSE),"") | O44: 46022 | P44: 45981 | Q44: 1 | R44: =IF($H44<>"Sí","",IF($I44="No implementado",IF(OR($N44="Muy alto",$N44="Alto"),"ALERTA ALTA","ALERTA"),IF(AND($I44="En proceso",OR($N44="Muy alto",$N44="Alto")),"EN PROCESO (riesgo alto)","")))
A45: A.6 | B45: DOM_A6 | C45: Personas | D45: A.6.7 | E45: Trabajo remoto seguro | F45: Define y aplica requisitos de seguridad para el trabajo a distancia, protegiendo accesos, dispositivos y datos. | G45: • Publicar política de trabajo remoto • exigir MFA/VPN • gestionar endpoints (MDM/EDR) • definir reglas BYOD • proteger datos (cifrado, DLP básico) • entrenar usuarios y revisar cumplimiento. | H45: =IF($I45="No aplicable","No","Sí") | N45: =IFERROR(VLOOKUP($M45,Riesgos!$A$2:$E$200,5,FALSE),"") | R45: =IF($H45<>"Sí","",IF($I45="No implementado",IF(OR($N45="Muy alto",$N45="Alto"),"ALERTA ALTA","ALERTA"),IF(AND($I45="En proceso",OR($N45="Muy alto",$N45="Alto")),"EN PROCESO (riesgo alto)","")))
A46: A.6 | B46: DOM_A6 | C46: Personas | D46: A.6.8 | E46: Reporte de eventos de seguridad de la información | F46: Establece canales y procedimiento para que el personal reporte eventos de seguridad de manera rápida y segura. | G46: • Definir canales (correo, portal, hotline) • comunicar a todo el personal • permitir reporte confidencial • definir SLA de triage • registrar y clasificar reportes • retroalimentar con comunicación y mejoras. | H46: =IF($I46="No aplicable","No","Sí") | N46: =IFERROR(VLOOKUP($M46,Riesgos!$A$2:$E$200,5,FALSE),"") | R46: =IF($H46<>"Sí","",IF($I46="No implementado",IF(OR($N46="Muy alto",$N46="Alto"),"ALERTA ALTA","ALERTA"),IF(AND($I46="En proceso",OR($N46="Muy alto",$N46="Alto")),"EN PROCESO (riesgo alto)","")))
A47: A.7 | B47: DOM_A7 | C47: Físicos | D47: A.7.1 | E47: Perímetros de seguridad física | F47: Define perímetros de seguridad física para proteger áreas y activos críticos frente a accesos no autorizados. | G47: • Delimitar zonas (público, restringido, crítico) • instalar barreras y controles • señalizar • revisar puntos de entrada • registrar visitantes • auditar periódicamente. | H47: =IF($I47="No aplicable","No","Sí") | N47: =IFERROR(VLOOKUP($M47,Riesgos!$A$2:$E$200,5,FALSE),"") | R47: =IF($H47<>"Sí","",IF($I47="No implementado",IF(OR($N47="Muy alto",$N47="Alto"),"ALERTA ALTA","ALERTA"),IF(AND($I47="En proceso",OR($N47="Muy alto",$N47="Alto")),"EN PROCESO (riesgo alto)","")))
A48: A.7 | B48: DOM_A7 | C48: Físicos | D48: A.7.2 | E48: Control de accesos/entradas físicas | F48: Controla la entrada física a instalaciones y áreas seguras mediante mecanismos de autenticación y registro. | G48: • Implementar credenciales/biometría según riesgo • gestionar altas/bajas de tarjetas • registrar accesos • supervisar visitantes • revisar logs • probar controles y respuesta ante fallos. | H48: =IF($I48="No aplicable","No","Sí") | I48: Implementado | J48: Control de acceso físico (credenciales/registro de visitas) y revisión periódica. | K48: Procedimiento visitas; bitácora; fotos de controles; reporte de revisión. | L48: Facilities / Seguridad Física | M48: R-006 | N48: =IFERROR(VLOOKUP($M48,Riesgos!$A$2:$E$200,5,FALSE),"") | O48: 46022 | P48: 45996 | Q48: 1 | R48: =IF($H48<>"Sí","",IF($I48="No implementado",IF(OR($N48="Muy alto",$N48="Alto"),"ALERTA ALTA","ALERTA"),IF(AND($I48="En proceso",OR($N48="Muy alto",$N48="Alto")),"EN PROCESO (riesgo alto)","")))
A49: A.7 | B49: DOM_A7 | C49: Físicos | D49: A.7.3 | E49: Protección de oficinas, salas e instalaciones | F49: Asegura oficinas, salas e instalaciones para prevenir acceso no autorizado y proteger equipos e información. | G49: • Evaluar riesgos por ubicación • instalar cerraduras y control de llaves • asegurar salas de servidores/archivo • gestionar alarmas • controlar acceso fuera de horario • registrar inspecciones. | H49: =IF($I49="No aplicable","No","Sí") | N49: =IFERROR(VLOOKUP($M49,Riesgos!$A$2:$E$200,5,FALSE),"") | R49: =IF($H49<>"Sí","",IF($I49="No implementado",IF(OR($N49="Muy alto",$N49="Alto"),"ALERTA ALTA","ALERTA"),IF(AND($I49="En proceso",OR($N49="Muy alto",$N49="Alto")),"EN PROCESO (riesgo alto)","")))
A50: A.7 | B50: DOM_A7 | C50: Físicos | D50: A.7.4 | E50: Monitoreo de seguridad física | F50: Monitorea seguridad física (p. ej., CCTV, sensores) para detectar y responder a incidentes de acceso o daño. | G50: • Definir áreas a monitorear • desplegar CCTV/sensores • retener grabaciones según política • proteger evidencias • revisar alertas • probar respuesta e integraciones con incidentes. | H50: =IF($I50="No aplicable","No","Sí") | N50: =IFERROR(VLOOKUP($M50,Riesgos!$A$2:$E$200,5,FALSE),"") | R50: =IF($H50<>"Sí","",IF($I50="No implementado",IF(OR($N50="Muy alto",$N50="Alto"),"ALERTA ALTA","ALERTA"),IF(AND($I50="En proceso",OR($N50="Muy alto",$N50="Alto")),"EN PROCESO (riesgo alto)","")))
A51: A.7 | B51: DOM_A7 | C51: Físicos | D51: A.7.5 | E51: Protección ante amenazas físicas y ambientales | F51: Protege contra amenazas físicas y ambientales (incendio, inundación, temperatura, humo, polvo) que afecten instalaciones y equipos. | G51: • Realizar evaluación de amenazas • instalar detección/extinción • controlar temperatura/humedad • definir mantenimiento preventivo • probar sistemas • registrar inspecciones y planes de mejora. | H51: =IF($I51="No aplicable","No","Sí") | N51: =IFERROR(VLOOKUP($M51,Riesgos!$A$2:$E$200,5,FALSE),"") | R51: =IF($H51<>"Sí","",IF($I51="No implementado",IF(OR($N51="Muy alto",$N51="Alto"),"ALERTA ALTA","ALERTA"),IF(AND($I51="En proceso",OR($N51="Muy alto",$N51="Alto")),"EN PROCESO (riesgo alto)","")))
...

Sheet Riesgos
A1: ID Riesgo | B1: Nombre / breve descripción | C1: Probabilidad (1-5) | D1: Impacto (1-5) | E1: Nivel (texto) | F1: Propietario | G1: Estado | H1: Comentarios
A2: R-001 | B2: Pérdida de disponibilidad por falla de infraestructura | C2: 3 | D2: 4 | E2: Alto | F2: TI | G2: Abierto
A3: R-002 | B3: Fuga de datos por acceso indebido | C3: 3 | D3: 5 | E3: Muy alto | F3: Seguridad | G3: Abierto
A4: R-003 | B4: Malware/ransomware en endpoints | C4: 4 | D4: 4 | E4: Muy alto | F4: TI | G4: Abierto
A5: R-004 | B5: Incumplimiento legal (PII) y sanciones | C5: 2 | D5: 5 | E5: Alto | F5: Legal/DPO | G5: Abierto
A6: R-005 | B6: Proveedor crítico sin controles suficientes | C6: 3 | D6: 4 | E6: Alto | F6: Compras | G6: Abierto
A7: R-006 | B7: Interrupción por desastre físico (incendio/inundación) | C7: 2 | D7: 5 | E7: Alto | F7: Operaciones | G7: Abierto
A8: R-007 | B8: Errores humanos por falta de capacitación | C8: 3 | D8: 3 | E8: Medio | F8: RR.HH. | G8: Abierto
A9: R-008 | B9: Vulnerabilidades sin parchear en sistemas | C9: 4 | D9: 4 | E9: Muy alto | F9: TI | G9: Abierto
A10: R-009 | B10: Cambios no controlados generan incidentes | C10: 3 | D10: 4 | E10: Alto | F10: TI | G10: Abierto
A11: R-010 | B11: Pérdida de evidencias ante un incidente | C11: 2 | D11: 4 | E11: Medio | F11: Seguridad | G11: Abierto

Sheet Listas
A1: Estados | C1: Dominios | F1: Niveles de riesgo | H1: Estados de riesgo
A2: Implementado | C2: A.5 | D2: Organizacionales | E2: DOM_A5 | F2: Muy alto | H2: Abierto
A3: En proceso | C3: A.6 | D3: Personas | E3: DOM_A6 | F3: Alto | H3: En tratamiento
A4: No implementado | C4: A.7 | D4: Físicos | E4: DOM_A7 | F4: Medio | H4: Aceptado
A5: No aplicable | C5: A.8 | D5: Tecnológicos | E5: DOM_A8 | F5: Bajo | H5: Cerrado
F6: Muy bajo

Sheet Dashboard
A1: Dashboard – Controles ISO/IEC 27001:2022
A2: Última actualización (hoy): | B2: =TODAY()
A4: Dominio | B4: Categoría | C4: Total | D4: Aplicables | E4: Implementados | F4: En proceso | G4: No implementados | H4: No aplicables | I4: % Implementado (sobre aplicables) | J4: Alertas (aplicable y no implementado)
A5: A.5 | B5: Organizacionales | C5: =COUNTIF(Controles!$B$2:$B$50,"DOM_A5")+COUNTIF(Controles!$B$51:$B$94,"DOM_A5") | D5: =COUNTIFS(Controles!$B$2:$B$50,"DOM_A5",Controles!$H$2:$H$50,"Sí")+COUNTIFS(Controles!$B$51:$B$94,"DOM_A5",Controles!$H$51:$H$94,"Sí") | E5: =COUNTIFS(Controles!$B$2:$B$50,"DOM_A5",Controles!$I$2:$I$50,"Implementado")+COUNTIFS(Controles!$B$51:$B$94,"DOM_A5",Controles!$I$51:$I$94,"Implementado") | F5: =COUNTIFS(Controles!$B$2:$B$50,"DOM_A5",Controles!$I$2:$I$50,"En proceso")+COUNTIFS(Controles!$B$51:$B$94,"DOM_A5",Controles!$I$51:$I$94,"En proceso") | G5: =COUNTIFS(Controles!$B$2:$B$50,"DOM_A5",Controles!$I$2:$I$50,"No implementado")+COUNTIFS(Controles!$B$51:$B$94,"DOM_A5",Controles!$I$51:$I$94,"No implementado") | H5: =COUNTIFS(Controles!$B$2:$B$50,"DOM_A5",Controles!$I$2:$I$50,"No aplicable")+COUNTIFS(Controles!$B$51:$B$94,"DOM_A5",Controles!$I$51:$I$94,"No aplicable") | I5: =IF(D5=0,0,E5/D5) | J5: =COUNTIFS(Controles!$B$2:$B$50,"DOM_A5",Controles!$R$2:$R$50,"ALERTA")+COUNTIFS(Controles!$B$2:$B$50,"DOM_A5",Controles!$R$2:$R$50,"ALERTA ALTA")+COUNTIFS(Controles!$B$51:$B$94,"DOM_A5",Controles!$R$51:$R$94,"ALERTA")+COUNTIFS(Controles!$B$51:$B$94,"DOM_A5",Controles!$R$51:$R$94,"ALERTA ALTA")
A6: A.6 | B6: Personas | C6: =COUNTIF(Controles!$B$2:$B$50,"DOM_A6")+COUNTIF(Controles!$B$51:$B$94,"DOM_A6") | D6: =COUNTIFS(Controles!$B$2:$B$50,"DOM_A6",Controles!$H$2:$H$50,"Sí")+COUNTIFS(Controles!$B$51:$B$94,"DOM_A6",Controles!$H$51:$H$94,"Sí") | E6: =COUNTIFS(Controles!$B$2:$B$50,"DOM_A6",Controles!$I$2:$I$50,"Implementado")+COUNTIFS(Controles!$B$51:$B$94,"DOM_A6",Controles!$I$51:$I$94,"Implementado") | F6: =COUNTIFS(Controles!$B$2:$B$50,"DOM_A6",Controles!$I$2:$I$50,"En proceso")+COUNTIFS(Controles!$B$51:$B$94,"DOM_A6",Controles!$I$51:$I$94,"En proceso") | G6: =COUNTIFS(Controles!$B$2:$B$50,"DOM_A6",Controles!$I$2:$I$50,"No implementado")+COUNTIFS(Controles!$B$51:$B$94,"DOM_A6",Controles!$I$51:$I$94,"No implementado") | H6: =COUNTIFS(Controles!$B$2:$B$50,"DOM_A6",Controles!$I$2:$I$50,"No aplicable")+COUNTIFS(Controles!$B$51:$B$94,"DOM_A6",Controles!$I$51:$I$94,"No aplicable") | I6: =IF(D6=0,0,E6/D6) | J6: =COUNTIFS(Controles!$B$2:$B$50,"DOM_A6",Controles!$R$2:$R$50,"ALERTA")+COUNTIFS(Controles!$B$2:$B$50,"DOM_A6",Controles!$R$2:$R$50,"ALERTA ALTA")+COUNTIFS(Controles!$B$51:$B$94,"DOM_A6",Controles!$R$51:$R$94,"ALERTA")+COUNTIFS(Controles!$B$51:$B$94,"DOM_A6",Controles!$R$51:$R$94,"ALERTA ALTA")
A7: A.7 | B7: Físicos | C7: =COUNTIF(Controles!$B$2:$B$50,"DOM_A7")+COUNTIF(Controles!$B$51:$B$94,"DOM_A7") | D7: =COUNTIFS(Controles!$B$2:$B$50,"DOM_A7",Controles!$H$2:$H$50,"Sí")+COUNTIFS(Controles!$B$51:$B$94,"DOM_A7",Controles!$H$51:$H$94,"Sí") | E7: =COUNTIFS(Controles!$B$2:$B$50,"DOM_A7",Controles!$I$2:$I$50,"Implementado")+COUNTIFS(Controles!$B$51:$B$94,"DOM_A7",Controles!$I$51:$I$94,"Implementado") | F7: =COUNTIFS(Controles!$B$2:$B$50,"DOM_A7",Controles!$I$2:$I$50,"En proceso")+COUNTIFS(Controles!$B$51:$B$94,"DOM_A7",Controles!$I$51:$I$94,"En proceso") | G7: =COUNTIFS(Controles!$B$2:$B$50,"DOM_A7",Controles!$I$2:$I$50,"No implementado")+COUNTIFS(Controles!$B$51:$B$94,"DOM_A7",Controles!$I$51:$I$94,"No implementado") | H7: =COUNTIFS(Controles!$B$2:$B$50,"DOM_A7",Controles!$I$2:$I$50,"No aplicable")+COUNTIFS(Controles!$B$51:$B$94,"DOM_A7",Controles!$I$51:$I$94,"No aplicable") | I7: =IF(D7=0,0,E7/D7) | J7: =COUNTIFS(Controles!$B$2:$B$50,"DOM_A7",Controles!$R$2:$R$50,"ALERTA")+COUNTIFS(Controles!$B$2:$B$50,"DOM_A7",Controles!$R$2:$R$50,"ALERTA ALTA")+COUNTIFS(Controles!$B$51:$B$94,"DOM_A7",Controles!$R$51:$R$94,"ALERTA")+COUNTIFS(Controles!$B$51:$B$94,"DOM_A7",Controles!$R$51:$R$94,"ALERTA ALTA")
A8: A.8 | B8: Tecnológicos | C8: =COUNTIF(Controles!$B$2:$B$50,"DOM_A8")+COUNTIF(Controles!$B$51:$B$94,"DOM_A8") | D8: =COUNTIFS(Controles!$B$2:$B$50,"DOM_A8",Controles!$H$2:$H$50,"Sí")+COUNTIFS(Controles!$B$51:$B$94,"DOM_A8",Controles!$H$51:$H$94,"Sí") | E8: =COUNTIFS(Controles!$B$2:$B$50,"DOM_A8",Controles!$I$2:$I$50,"Implementado")+COUNTIFS(Controles!$B$51:$B$94,"DOM_A8",Controles!$I$51:$I$94,"Implementado") | F8: =COUNTIFS(Controles!$B$2:$B$50,"DOM_A8",Controles!$I$2:$I$50,"En proceso")+COUNTIFS(Controles!$B$51:$B$94,"DOM_A8",Controles!$I$51:$I$94,"En proceso") | G8: =COUNTIFS(Controles!$B$2:$B$50,"DOM_A8",Controles!$I$2:$I$50,"No implementado")+COUNTIFS(Controles!$B$51:$B$94,"DOM_A8",Controles!$I$51:$I$94,"No implementado") | H8: =COUNTIFS(Controles!$B$2:$B$50,"DOM_A8",Controles!$I$2:$I$50,"No aplicable")+COUNTIFS(Controles!$B$51:$B$94,"DOM_A8",Controles!$I$51:$I$94,"No aplicable") | I8: =IF(D8=0,0,E8/D8) | J8: =COUNTIFS(Controles!$B$2:$B$50,"DOM_A8",Controles!$R$2:$R$50,"ALERTA")+COUNTIFS(Controles!$B$2:$B$50,"DOM_A8",Controles!$R$2:$R$50,"ALERTA ALTA")+COUNTIFS(Controles!$B$51:$B$94,"DOM_A8",Controles!$R$51:$R$94,"ALERTA")+COUNTIFS(Controles!$B$51:$B$94,"DOM_A8",Controles!$R$51:$R$94,"ALERTA ALTA")
A9: TOTAL | C9: =SUM(C5:C8) | D9: =SUM(D5:D8) | E9: =SUM(E5:E8) | F9: =SUM(F5:F8) | G9: =SUM(G5:G8) | H9: =SUM(H5:H8) | I9: =IF(D9=0,0,E9/D9) | J9: =SUM(J5:J8)
